<?xml version="1.0" ?>
<robot xmlns:xacro="http://ros.org/wiki/xacro">
<xacro:macro name="atturtle" params="prefix">
    <xacro:include filename="$(find atturtle_description)/urdf/common_properties.xacro"/>

    <!-- link list -->
    <!-- base_footprint is a fictitious link(frame) that is on the ground right below link_base origin, navigation stack depends on this frame -->
    <link name="base_footprint">
        <visual>
            <origin xyz="0 0 0" rpy="0 0 0" />
            <geometry>
                <box size="0.001 0.001 0.001" />
            </geometry>
            <xacro:material_green/>
        </visual>
        <collision>
            <origin xyz="0 0 0.017" rpy="0 0 0" />
            <geometry>
                <box size="0.001 0.001 0.001" />
            </geometry>
          </collision>
    </link>
    <link  name="${prefix}link_base">
        <visual>
            <origin xyz="0 0 0.025" rpy="0 0 0" />
            <geometry>
                <cylinder length="0.0635" radius="0.15875"/>
            </geometry>
            <xacro:material_light_grey/>
        </visual>
        <collision>
            <origin xyz="0 0 0.025" rpy="0 0 0" />
            <geometry>
                <cylinder length="0.0635" radius="0.15875"/>
            </geometry>
        </collision>
    </link>
    <link name="${prefix}left_wheel_link">
	    <visual>
	        <origin xyz="0 0 0" rpy="0 1.5707 1.5707" />
	        <geometry>
	            <cylinder radius="0.033" length = "0.023"/>
	        </geometry>
	    </visual>
	    <collision>
	        <origin xyz="0 0 0" rpy="0 1.5707 1.5707" />
	        <geometry>
	            <cylinder radius="0.033" length = "0.023"/>
	        </geometry>
	    </collision>
	</link>
    <link name="${prefix}right_wheel_link">
	    <visual>
	        <origin xyz="0 0 0" rpy="0 1.5707 1.5707" />
	        <geometry>
	            <cylinder radius="0.033" length = "0.023"/>
	        </geometry>
	    </visual>
	    <collision>
	        <origin xyz="0 0 0" rpy="0 1.5707 1.5707" />
	        <geometry>
	            <cylinder radius="0.033" length = "0.023"/>
	        </geometry>
	    </collision>
	</link>
    <link name="${prefix}rear_wheel_link">
        <visual>
            <origin xyz="0 0 0" rpy="0 1.5707 1.5707"/>
            <geometry>
                <sphere radius="0.015" />
            </geometry>
        </visual>
        <collision>
            <origin xyz="0 0 0" rpy="0 1.5707 1.5707" />
            <geometry>
                <sphere radius="0.015" />
            </geometry>
        </collision>
    </link>
    <!-- end of link list -->



    <!-- joint list -->
    <joint name="${prefix}footprint-base" type="fixed">
        <origin xyz="0 0 0.017" rpy="0 0 0" />        
        <parent link="${prefix}base_footprint"/>
        <child link="${prefix}link_base" />
    </joint>
    <joint name="${prefix}left_wheel_joint" type="continuous">
	    <origin xyz="0 0.1016 0.015" rpy="0 0 0"/>
	    <parent link="${prefix}link_base"/>
	    <child link="${prefix}left_wheel_link"/>
	    <axis xyz="0 1 0"/>
        <limit effort="100" velocity="100"/>
        <joint_properties damping="0.0" friction="0.0"/>
    </joint>
    <joint name="${prefix}right_wheel_joint" type="continuous">
	    <origin xyz="0 -0.1016 0.015" rpy="0 0 0"/>
	    <parent link="${prefix}link_base"/>
	    <child link="${prefix}right_wheel_link"/>
	    <axis xyz="0 1 0"/>
        <limit effort="100" velocity="100"/>
        <joint_properties damping="0.0" friction="0.0"/>
    </joint>
    <joint name="${prefix}rear_castor_joint" type="fixed">
	    <origin xyz="0.1143 0 0" rpy="0 0 0"/>
	    <parent link="${prefix}link_base"/>
	    <child link="${prefix}rear_wheel_link"/>
	    <axis xyz="0 1 0"/>
	</joint>
    <!-- end of joint list -->
</xacro:macro>
</robot>
